<mujoco model="NaoH25V50">
  <compiler angle="radian" meshdir="meshes/"/>

  <!-- https://github.com/HULKs/hulk/blob/main/webots/protos/NAO.proto  Could be useful later -->

<default>
    <light castshadow="false" diffuse="1 1 1"/>
    <joint damping="1" armature="0.1"/>

    <default class="collision_1">
      <geom rgba="1 0 0 0.5" margin="0.000" contype="2" conaffinity="1"/>
    </default>

    <default class="collision_2">
      <geom rgba="1 0 0 0.5" margin="0.000" contype="4" conaffinity="1"/>
    </default>

    <default class="collision_3">
      <geom rgba="1 0 0 0.5" margin="0.000" contype="8" conaffinity="1"/>
    </default>

    <default class="collision_4">
      <geom rgba="1 0 0 0.5" margin="0.000" contype="16" conaffinity="1"/>
    </default>

    <default class="visual">
      <geom rgba="0 0 1 0.5" margin="0.000" contype="0" conaffinity="0"/>
    </default>

    
</default>
  
  <asset>
    <mesh name="HeadYaw" file="HeadYaw.obj" scale="0.1 0.1 0.1"/>
    <mesh name="HeadYaw_0.10" file="HeadYaw_0.10.stl" scale="0.1 0.1 0.1"/>

    <mesh name="HeadPitch" file="HeadPitch.obj" scale="0.1 0.1 0.1"/>
    <mesh name="HeadPitch_0.10" file="HeadPitch_0.10.stl" scale="0.1 0.1 0.1"/>

    <mesh name="LHipYawPitch" file="LHipYawPitch.obj" scale="0.1 0.1 0.1"/>
    <mesh name="LHipYawPitch_0.10" file="LHipYawPitch_0.10.stl" scale="0.1 0.1 0.1"/>

    <mesh name="LHipRoll" file="LHipRoll.obj" scale="0.1 0.1 0.1"/>
    <mesh name="LHipRoll_0.10" file="LHipRoll_0.10.stl" scale="0.1 0.1 0.1"/>

    <mesh name="LHipPitch" file="LHipPitch.obj" scale="0.1 0.1 0.1"/>
    <mesh name="LHipPitch_0.10" file="LHipPitch_0.10.stl" scale="0.1 0.1 0.1"/>

    <mesh name="LKneePitch" file="LKneePitch.obj" scale="0.1 0.1 0.1"/>
    <mesh name="LKneePitch_0.10" file="LKneePitch_0.10.stl" scale="0.1 0.1 0.1"/>

    <mesh name="LAnklePitch" file="LAnklePitch.obj" scale="0.1 0.1 0.1"/>
    <mesh name="LAnklePitch_0.10" file="LAnklePitch_0.10.stl" scale="0.1 0.1 0.1"/>

    <mesh name="LAnkleRoll" file="LAnkleRoll.obj" scale="0.1 0.1 0.1"/>
    <mesh name="LAnkleRoll_0.10" file="LAnkleRoll_0.10.stl" scale="0.1 0.1 0.1"/>

    <mesh name="RHipYawPitch" file="RHipYawPitch.obj" scale="0.1 0.1 0.1"/>
    <mesh name="RHipYawPitch_0.10" file="RHipYawPitch_0.10.stl" scale="0.1 0.1 0.1"/>

    <mesh name="RHipRoll" file="RHipRoll.obj" scale="0.1 0.1 0.1"/>
    <mesh name="RHipRoll_0.10" file="RHipRoll_0.10.stl" scale="0.1 0.1 0.1"/>

    <mesh name="RHipPitch" file="RHipPitch.obj" scale="0.1 0.1 0.1"/>
    <mesh name="RHipPitch_0.10" file="RHipPitch_0.10.stl" scale="0.1 0.1 0.1"/>

    <mesh name="RKneePitch" file="RKneePitch.obj" scale="0.1 0.1 0.1"/>
    <mesh name="RKneePitch_0.10" file="RKneePitch_0.10.stl" scale="0.1 0.1 0.1"/>

    <mesh name="RAnklePitch" file="RAnklePitch.obj" scale="0.1 0.1 0.1"/>
    <mesh name="RAnklePitch_0.10" file="RAnklePitch_0.10.stl" scale="0.1 0.1 0.1"/>

    <mesh name="RAnkleRoll" file="RAnkleRoll.obj" scale="0.1 0.1 0.1"/>
    <mesh name="RAnkleRoll_0.10" file="RAnkleRoll_0.10.stl" scale="0.1 0.1 0.1"/>

    <mesh name="Torso" file="Torso.obj" scale="0.1 0.1 0.1"/>
    <mesh name="Torso_0.10" file="Torso_0.10.stl" scale="0.1 0.1 0.1"/>

    <mesh name="LShoulderPitch" file="LShoulderPitch.obj" scale="0.1 0.1 0.1"/>
    <mesh name="LShoulderPitch_0.10" file="LShoulderPitch_0.10.stl" scale="0.1 0.1 0.1"/>

    <mesh name="LShoulderRoll" file="LShoulderRoll.obj" scale="0.1 0.1 0.1"/>
    <mesh name="LShoulderRoll_0.10" file="LShoulderRoll_0.10.stl" scale="0.1 0.1 0.1"/>

    <mesh name="LElbowRoll" file="LElbowRoll.obj" scale="0.1 0.1 0.1"/>
    <mesh name="LElbowRoll_0.10" file="LElbowRoll_0.10.stl" scale="0.1 0.1 0.1"/>

    <mesh name="LWristYaw" file="LWristYaw.obj" scale="0.1 0.1 0.1"/>
    <mesh name="LWristYaw_0.10" file="LWristYaw_0.10.stl" scale="0.1 0.1 0.1"/>

    <mesh name="RShoulderPitch" file="RShoulderPitch.obj" scale="0.1 0.1 0.1"/>
    <mesh name="RShoulderPitch_0.10" file="RShoulderPitch_0.10.stl" scale="0.1 0.1 0.1"/>

    <mesh name="RShoulderRoll" file="RShoulderRoll.obj" scale="0.1 0.1 0.1"/>
    <mesh name="RShoulderRoll_0.10" file="RShoulderRoll_0.10.stl" scale="0.1 0.1 0.1"/>

    <mesh name="RElbowRoll" file="RElbowRoll.obj" scale="0.1 0.1 0.1"/>
    <mesh name="RElbowRoll_0.10" file="RElbowRoll_0.10.stl" scale="0.1 0.1 0.1"/>

    <mesh name="RWristYaw" file="RWristYaw.obj" scale="0.1 0.1 0.1"/>
    <mesh name="RWristYaw_0.10" file="RWristYaw_0.10.stl" scale="0.1 0.1 0.1"/>

    <mesh name="RFinger13" file="RFinger13.obj" scale="0.1 0.1 0.1"/>
    <mesh name="RFinger13_0.10" file="RFinger13_0.10.stl" scale="0.1 0.1 0.1"/>

    <mesh name="RFinger12" file="RFinger12.obj" scale="0.1 0.1 0.1"/>
    <mesh name="RFinger12_0.10" file="RFinger12_0.10.stl" scale="0.1 0.1 0.1"/>

    <mesh name="LFinger21" file="LFinger21.obj" scale="0.1 0.1 0.1"/>
    <mesh name="LFinger21_0.10" file="LFinger21_0.10.stl" scale="0.1 0.1 0.1"/>

    <mesh name="LFinger13" file="LFinger13.obj" scale="0.1 0.1 0.1"/>
    <mesh name="LFinger13_0.10" file="LFinger13_0.10.stl" scale="0.1 0.1 0.1"/>

    <mesh name="LFinger11" file="LFinger11.obj" scale="0.1 0.1 0.1"/>
    <mesh name="LFinger11_0.10" file="LFinger11_0.10.stl" scale="0.1 0.1 0.1"/>

    <mesh name="RFinger22" file="RFinger22.obj" scale="0.1 0.1 0.1"/>
    <mesh name="RFinger22_0.10" file="RFinger22_0.10.stl" scale="0.1 0.1 0.1"/>

    <mesh name="LFinger22" file="LFinger22.obj" scale="0.1 0.1 0.1"/>
    <mesh name="LFinger22_0.10" file="LFinger22_0.10.stl" scale="0.1 0.1 0.1"/>

    <mesh name="RFinger21" file="RFinger21.obj" scale="0.1 0.1 0.1"/>
    <mesh name="RFinger21_0.10" file="RFinger21_0.10.stl" scale="0.1 0.1 0.1"/>

    <mesh name="LFinger12" file="LFinger12.obj" scale="0.1 0.1 0.1"/>
    <mesh name="LFinger12_0.10" file="LFinger12_0.10.stl" scale="0.1 0.1 0.1"/>

    <mesh name="RFinger23" file="RFinger23.obj" scale="0.1 0.1 0.1"/>
    <mesh name="RFinger23_0.10" file="RFinger23_0.10.stl" scale="0.1 0.1 0.1"/>

    <mesh name="RFinger11" file="RFinger11.obj" scale="0.1 0.1 0.1"/>
    <mesh name="RFinger11_0.10" file="RFinger11_0.10.stl" scale="0.1 0.1 0.1"/>

    <mesh name="LFinger23" file="LFinger23.obj" scale="0.1 0.1 0.1"/>
    <mesh name="LFinger23_0.10" file="LFinger23_0.10.stl" scale="0.1 0.1 0.1"/>

    <mesh name="LThumb1" file="LThumb1.obj" scale="0.1 0.1 0.1"/>
    <mesh name="LThumb1_0.10" file="LThumb1_0.10.stl" scale="0.1 0.1 0.1"/>

    <mesh name="RThumb1" file="RThumb1.obj" scale="0.1 0.1 0.1"/>
    <mesh name="RThumb1_0.10" file="RThumb1_0.10.stl" scale="0.1 0.1 0.1"/>

    <mesh name="RThumb2" file="RThumb2.obj" scale="0.1 0.1 0.1"/>
    <mesh name="RThumb2_0.10" file="RThumb2_0.10.stl" scale="0.1 0.1 0.1"/>

    <mesh name="LThumb2" file="LThumb2.obj" scale="0.1 0.1 0.1"/>
    <mesh name="LThumb2_0.10" file="LThumb2_0.10.stl" scale="0.1 0.1 0.1"/>
  </asset>

  <worldbody>
    <light directional="true" diffuse=".8 .8 .8" pos="0 0 10" dir="0 0 -10"/>
    
    <body name="torso" pos="0 0 0.35">
      <site name="accelerometer_site" pos="-0.008 0.00606 0.027"/>
      <site name="gyrometer_site" pos="-0.008 0.006 0.029"/>
      <inertial pos="-0.00413 0 0.04342" mass="1.04956" diaginertia="0.00308361 0.0028835 0.0015924"/>
      <joint type="free"/>
      <geom type="mesh" rgba="0.3 0.1 0.5 1" mesh="Torso_0.10" class="collision_1"/>
      <body name="Neck" pos="0 0 0.1265">
        <inertial pos="-1e-05 0 -0.02742" quat="0.70765 -0.00173495 0.00151894 0.706559" mass="0.07842" diaginertia="1.70396e-05 1.60324e-05 5.53348e-06"/>
        <joint name="HeadYaw" pos="0 0 0" axis="0 0 1" range="-2.08567 2.08567" actuatorfrcrange="-1.547 1.547"/>
        <geom type="mesh" rgba="0.5 1 0.5 1" mesh="HeadYaw_0.10" class="visual"/>
        <body name="Head">
          <inertial pos="-0.00112 0 0.05258" quat="0.463877 0.585354 -0.492966 0.446277" mass="0.60533" diaginertia="0.000990592 0.000957952 0.000811033"/>
          <joint name="HeadPitch" pos="0 0 0" axis="0 1 0" range="-0.671952 0.514872" actuatorfrcrange="-1.532 1.532"/>
          <geom type="mesh" rgba="1 0.3 0.5 1" mesh="HeadPitch_0.10" class="collision_2"/>

          <camera name="TopCamera" mode="fixed" pos="0 0 0.1" fovy="72.6"/>
          <camera name="BottomCamera" mode="fixed" pos="0 0 -0.1" fovy="72.6"/>
        </body>
      </body>
      <body name="LPelvis" pos="0 0.05 -0.085">
        <inertial pos="-0.00781 -0.01114 0.02661" quat="0.232303 0.656505 0.182148 0.69416" mass="0.06981" diaginertia="5.16414e-05 4.58792e-05 2.32239e-05"/>
        <joint name="LHipYawPitch" pos="0 0 0" axis="0 0.707107 -0.707107" range="-1.14529 0.740718" actuatorfrcrange="-3.348 3.348"/>
        <geom type="mesh" rgba="1 0.423529 0.0392157 1" mesh="LHipYawPitch_0.10" class="collision_2"/>
        <body name="LHip">
          <inertial pos="-0.01549 0.00029 -0.00515" quat="0.453959 0.527953 0.574067 0.430853" mass="0.14053" diaginertia="6.08587e-05 5.59269e-05 2.22526e-05"/>
          <joint name="LHipRoll" pos="0 0 0" axis="1 0 0" range="-0.379435 0.79046" actuatorfrcrange="-3.348 3.348"/>
          <geom type="mesh" rgba="1 0.423529 0.0392157 1" mesh="LHipRoll_0.10" class="collision_3"/>
          <body name="LThigh">
            <inertial pos="0.00138 0.00221 -0.05373" quat="0.992078 -0.0228023 -0.123519 -0.00190301" mass="0.38968" diaginertia="0.000524114 0.000465732 0.000286453"/>
            <joint name="LHipPitch" pos="0 0 0" axis="0 1 0" range="-1.53589 0.48398" actuatorfrcrange="-3.023 3.023"/>
            <geom type="mesh" rgba="1 0.3 0.5 1" mesh="LHipPitch_0.10" class="collision_4"/>
            <body name="LTibia" pos="0 0 -0.1">
              <inertial pos="0.00453 0.00225 -0.04936" quat="0.997907 0.0169027 0.0579417 0.0232071" mass="0.30142" diaginertia="0.000449928 0.000388139 0.000181704"/>
              <joint name="LKneePitch" pos="0 0 0" axis="0 1 0" range="-0.0923279 2.11255" actuatorfrcrange="-3.023 3.023"/>
              <geom type="mesh" rgba="0.8 0.4 0.9 1" mesh="LKneePitch_0.10" class="collision_1"/>
              <body name="LAnklePitch" pos="0 0 -0.1029">
                <inertial pos="0.00045 0.00029 0.00685" quat="0.447256 0.548803 0.537287 0.458368" mass="0.13416" diaginertia="6.79494e-05 5.56016e-05 3.14223e-05"/>
                <joint name="LAnklePitch" pos="0 0 0" axis="0 1 0" range="-1.18944 0.922581" actuatorfrcrange="-3.023 3.023"/>
                <geom type="mesh" rgba="0.5 0.7 1 1" mesh="LAnklePitch_0.10" class="collision_4"/>
                <body name="l_ankle">
                  <inertial pos="0.0254198 0.00330005 -0.0323906" quat="0.0134363 0.704739 -0.00974782 0.709273" mass="0.171848" diaginertia="0.000412891 0.000353334 8.70025e-05"/>
                  <joint name="LAnkleRoll" pos="0 0 0" axis="1 0 0" range="-0.397761 0.768992" actuatorfrcrange="-3.348 3.348"/>
                  <geom type="mesh" rgba="0.5 0.7 1 1" mesh="LAnkleRoll_0.10" class="collision_2"/>
                  <geom size="0.005 0.005 0.001" pos="0.07025 -0.0231 -0.04511" type="box"/>
                  <geom size="0.005 0.005 0.001" pos="0.07025 -0.0231 -0.04511" type="box" density="0" rgba="0.3 0.3 0.3 1"/>
                  <geom size="0.005 0.005 0.001" pos="-0.02965 -0.0191 -0.04511" type="box"/>
                  <geom size="0.005 0.005 0.001" pos="-0.02965 -0.0191 -0.04511" type="box" density="0" rgba="0.3 0.3 0.3 1"/>
                  <geom size="0.005 0.005 0.001" pos="0.07025 0.0299 -0.04511" type="box"/>
                  <geom size="0.005 0.005 0.001" pos="0.07025 0.0299 -0.04511" type="box" density="0" rgba="0.3 0.3 0.3 1"/>
                  <geom size="0.005 0.005 0.001" pos="-0.03025 0.0299 -0.04511" type="box"/>
                  <geom size="0.005 0.005 0.001" pos="-0.03025 0.0299 -0.04511" type="box" density="0" rgba="0.3 0.3 0.3 1"/>

                  <site name="LFsrFL_site" pos="0.07025 0.0299 -0.046"/>
                  <site name="LFsrFR_site" pos="0.07025 -0.0231 -0.046"/>
                  <site name="LFsrRL_site" pos="-0.03025 0.0299 -0.046"/>
                  <site name="LFsrRR_site" pos="-0.02965 -0.0191 -0.046"/>

                  <site name="BumperLFootLeft_site" pos="0.099 0.0190 -0.0353"/>
                  <site name="BumperLFootRight_site" pos="0.099 -0.0140 -0.0353"/>
                </body>
              </body>
            </body>
          </body>
        </body>
      </body>
      <body name="RPelvis" pos="0 -0.05 -0.085">
        <inertial pos="-0.00781 0.01114 0.02661" quat="-0.286295 0.637526 -0.200888 0.686469" mass="0.06981" diaginertia="6.0003e-05 4.60859e-05 3.15895e-05"/>
        <joint name="RHipYawPitch" pos="0 0 0" axis="0 0.707107 0.707107" range="-1.14529 0.740718" actuatorfrcrange="-3.348 3.348"/>
        <geom type="mesh" rgba="0.3 0.1 0.6 1" mesh="RHipYawPitch_0.10" class="collision_2"/>
        <body name="RHip">
          <inertial pos="-0.01549 -0.00029 -0.00515" quat="0.431269 0.573083 0.528698 0.453941" mass="0.14053" diaginertia="6.08554e-05 5.59208e-05 2.2268e-05"/>
          <joint name="RHipRoll" pos="0 0 0" axis="1 0 0" range="-0.79046 0.379435" actuatorfrcrange="-3.348 3.348"/>
          <geom type="mesh" rgba="0.3 0.1 0.6 1" mesh="RHipRoll_0.10" class="collision_3"/>
          <body name="RThigh">
            <inertial pos="0.00138 -0.00221 -0.05373" quat="0.99203 0.0205489 -0.124311 0.000726212" mass="0.38968" diaginertia="0.000525121 0.000466802 0.000286518"/>
            <joint name="RHipPitch" pos="0 0 0" axis="0 1 0" range="-1.53589 0.48398" actuatorfrcrange="-3.0226 3.0226"/>
            <geom type="mesh" rgba="0.8 0.2 1 1" mesh="RHipPitch_0.10" class="collision_4"/>
            <body name="RTibia" pos="0 0 -0.1">
              <inertial pos="0.00453 -0.00225 -0.04936" quat="0.99698 -0.0149083 0.0724691 -0.0235809" mass="0.30142" diaginertia="0.000452851 0.000387699 0.000177824"/>
              <joint name="RKneePitch" pos="0 0 0" axis="0 1 0" range="-0.0923279 2.11255" actuatorfrcrange="-3.0226 3.0226"/>
              <geom type="mesh" rgba="0.8 0.2 1 1" mesh="RKneePitch_0.10" class="collision_4"/>
              <body name="RAnklePitch" pos="0 0 -0.1029">
                <inertial pos="0.00045 -0.00029 0.00685" quat="0.458219 0.537985 0.54818 0.447332" mass="0.13416" diaginertia="6.79942e-05 5.56532e-05 3.14175e-05"/>
                <joint name="RAnklePitch" pos="0 0 0" axis="0 1 0" range="-1.1863 0.932006" actuatorfrcrange="-3.0226 3.0226"/>
                <geom type="mesh" rgba="0.1 0.4 0.6 1" mesh="RAnklePitch_0.10" class="collision_2"/>
                <body name="r_ankle">
                  <inertial pos="0.0254198 -0.00330005 -0.0323906" quat="-0.0138336 0.704473 0.00894574 0.70954" mass="0.171848" diaginertia="0.000412175 0.000352454 8.68701e-05"/>
                  <joint name="RAnkleRoll" pos="0 0 0" axis="1 0 0" range="-0.768992 0.397761" actuatorfrcrange="-3.348 3.348"/>
                  <geom type="mesh" rgba="0.1 0.4 0.6 1" mesh="RAnkleRoll_0.10" class="collision_3"/>
                  <geom size="0.005 0.005 0.001" pos="-0.03025 0.0191 -0.04511" type="box"/>
                  <geom size="0.005 0.005 0.001" pos="-0.03025 0.0191 -0.04511" type="box" density="0" rgba="0.3 0.3 0.3 1"/>
                  <geom size="0.005 0.005 0.001" pos="-0.02965 -0.0299 -0.04511" type="box"/>
                  <geom size="0.005 0.005 0.001" pos="-0.02965 -0.0299 -0.04511" type="box" density="0" rgba="0.3 0.3 0.3 1"/>
                  <geom size="0.005 0.005 0.001" pos="0.07025 -0.0299 -0.04511" type="box"/>
                  <geom size="0.005 0.005 0.001" pos="0.07025 -0.0299 -0.04511" type="box" density="0" rgba="0.3 0.3 0.3 1"/>
                  <geom size="0.005 0.005 0.001" pos="0.07025 0.0231 -0.04511" type="box"/>
                  <geom size="0.005 0.005 0.001" pos="0.07025 0.0231 -0.04511" type="box" density="0" rgba="0.3 0.3 0.3 1"/>

                  <site name="RFsrFL_site" pos="0.07025 0.0231 -0.046"/>
                  <site name="RFsrFR_site" pos="0.07025 -0.0299 -0.046"/>
                  <site name="RFsrRL_site" pos="-0.03025 0.0191 -0.046"/>
                  <site name="RFsrRR_site" pos="-0.02965 -0.0299 -0.046"/>

                  <site name="BumperRFootLeft_site" pos="0.099 0.0140 -0.0353"/>
                  <site name="BumperRFootRight_site" pos="0.099 -0.0190 -0.0353"/>
                </body>
              </body>
            </body>
          </body>
        </body>
      </body>
      <body name="LShoulder" pos="0 0.098 0.1">
        <inertial pos="-0.00165 -0.02663 0.00014" quat="0.353499 0.572853 -0.442525 0.592494" mass="0.09304" diaginertia="2.02186e-05 1.91002e-05 1.30704e-05"/>
        <joint name="LShoulderPitch" pos="0 0 0" axis="0 1 0" range="-2.08567 2.08567" actuatorfrcrange="-1.329 1.329" ref="-1.5"/>
        <geom type="mesh" rgba="0.8 0.2 0.8 1" mesh="LShoulderPitch_0.10" class="collision_3"/>
        <body name="LBicep">
          <inertial pos="0.02455 0.00563 0.0033" quat="0.467645 0.46185 0.492756 0.570257" mass="0.15777" diaginertia="0.00027823 0.000242894 8.25818e-05"/>
          <joint name="LShoulderRoll" pos="0 0 0" axis="0 0 1" range="-0.314159 1.32645" actuatorfrcrange="-1.7835 1.7835"/>
          <geom type="mesh" rgba="0.2 0.5 0.5 1" mesh="LShoulderRoll_0.10" class="collision_4"/>
          <body name="LElbow" pos="0.105 0.015 0">
            <inertial pos="-0.02744 0 -0.00014" quat="-0.000545392 0.711779 -0.000696018 0.702403" mass="0.06483" diaginertia="2.76333e-05 2.66179e-05 5.592e-06"/>
            <joint name="LElbowYaw" pos="0 0 0" axis="1 0 0" range="-2.08567 2.08567" actuatorfrcrange="-1.547 1.547"/>
            <body name="LForeArm">
              <inertial pos="0.02556 0.00281 0.00076" quat="0.481839 0.619088 0.422287 0.454131" mass="0.07761" diaginertia="3.9183e-05 3.6083e-05 2.37632e-05"/>
              <joint name="LElbowRoll" pos="0 0 0" axis="0 0 1" range="-1.54462 -0.0349066" actuatorfrcrange="-1.532 1.532"/>
              <geom type="mesh" rgba="0.5 1 0.5 1" mesh="LElbowRoll_0.10" class="collision_1"/>
              <body name="l_wrist" pos="0.05595 0 0">
                <inertial pos="0.03434 -0.00088 0.00308" quat="0.346526 0.607704 0.329318 0.634165" mass="0.18533" diaginertia="0.000137482 0.000131631 6.85194e-05"/>
                <joint name="LWristYaw" pos="0 0 0" axis="1 0 0" range="-1.82387 1.82387" actuatorfrcrange="-0.4075 0.4075" ref="1.57"/>
                <geom type="mesh" rgba="1 0.3 0.5 1" mesh="LWristYaw_0.10" class="collision_2"/>
                <body name="l_gripper" pos="0.05775 0 -0.01231">
                  <inertial pos="0 0 0" mass="2e-06" diaginertia="1.1e-09 1.1e-09 1.1e-09"/>
                  <joint name="LHand" pos="0 0 0" axis="1 0 0" range="0 1" actuatorfrcrange="-0.292 0.292"/>
                </body>
                <body name="LFinger21_link" pos="0.06907 -0.01157 -0.00304" quat="0.672286 0.564114 0.308141 -0.367227">
                  <inertial pos="0 0 0" mass="2e-06" diaginertia="1.1e-09 1.1e-09 1.1e-09"/>
                  <joint name="LFinger21" pos="0 0 0" axis="0 0 1" range="0 0.999899" actuatorfrcrange="-0.144 0.144"/>
                  <geom quat="0.707388 -0.706825 0 0" type="mesh" rgba="0.1 0.1 0.1 0.4" mesh="LFinger21_0.10" class="visual"/>
                  <body name="LFinger22_link" pos="0.01436 0 0" quat="0.877607 0 0 -0.479381">
                    <inertial pos="0 0 0" mass="2e-06" diaginertia="1.1e-09 1.1e-09 1.1e-09"/>
                    <joint name="LFinger22" pos="0 0 0" axis="0 0 1" range="0 0.999899" actuatorfrcrange="-0.144 0.144"/>
                    <geom quat="0.707388 -0.706825 0 0" type="mesh" rgba="0.1 0.1 0.1 0.4" mesh="LFinger22_0.10" class="visual"/>
                    <body name="LFinger23_link" pos="0.01436 0 0" quat="0.877607 0 0 -0.479381">
                      <inertial pos="0 0 0" mass="2e-06" diaginertia="1.1e-09 1.1e-09 1.1e-09"/>
                      <joint name="LFinger23" pos="0 0 0" axis="0 0 1" range="0 0.999899" actuatorfrcrange="-0.144 0.144"/>
                      <geom quat="0.707388 -0.706825 0 0" type="mesh" rgba="0.1 0.1 0.1 0.4" mesh="LFinger23_0.10" class="visual"/>
                    </body>
                  </body>
                </body>
                <body name="LFinger11_link" pos="0.06907 0.01157 -0.00304" quat="0.564115 0.672285 0.367228 -0.30814">
                  <inertial pos="0 0 0" mass="2e-06" diaginertia="1.1e-09 1.1e-09 1.1e-09"/>
                  <joint name="LFinger11" pos="0 0 0" axis="0 0 1" range="0 0.999899" actuatorfrcrange="-0.144 0.144"/>
                  <geom quat="0.707388 -0.706825 0 0" type="mesh" rgba="0.1 0.1 0.1 0.4" mesh="LFinger11_0.10" class="visual"/>
                  <body name="LFinger12_link" pos="0.01436 0 0" quat="0.877607 0 0 -0.479381">
                    <inertial pos="0 0 0" mass="2e-06" diaginertia="1.1e-09 1.1e-09 1.1e-09"/>
                    <joint name="LFinger12" pos="0 0 0" axis="0 0 1" range="0 0.999899" actuatorfrcrange="-0.144 0.144"/>
                    <geom quat="0.707388 -0.706825 0 0" type="mesh" rgba="0.1 0.1 0.1 0.4" mesh="LFinger12_0.10" class="visual"/>
                    <body name="LFinger13_link" pos="0.01436 0 0" quat="0.877607 0 0 -0.479381">
                      <inertial pos="0 0 0" mass="2e-06" diaginertia="1.1e-09 1.1e-09 1.1e-09"/>
                      <joint name="LFinger13" pos="0 0 0" axis="0 0 1" range="0 0.999899" actuatorfrcrange="-0.144 0.144"/>
                      <geom quat="0.707388 -0.706825 0 0" type="mesh" rgba="0.1 0.1 0.1 0.4" mesh="LFinger13_0.10" class="visual"/>
                    </body>
                  </body>
                </body>
                <body name="LThumb1_link" pos="0.04895 0 -0.02638" quat="0.706908 -0.70691 0.0167209 0.016721">
                  <inertial pos="0 0 0" mass="2e-06" diaginertia="1.1e-09 1.1e-09 1.1e-09"/>
                  <joint name="LThumb1" pos="0 0 0" axis="0 0 1" range="0 0.999899" actuatorfrcrange="-0.144 0.144"/>
                  <geom quat="0.620809 0.620315 -0.338839 -0.339109" type="mesh" rgba="0.1 0.1 0.1 0.4" mesh="LThumb1_0.10" class="visual"/>
                  <body name="LThumb2_link" pos="0.01236 -0.0015 0" quat="0.877607 0 0 -0.479381">
                    <inertial pos="0 0 0" mass="2e-06" diaginertia="1.1e-09 1.1e-09 1.1e-09"/>
                    <joint name="LThumb2" pos="0 0 0" axis="0 0 1" range="0 0.999899" actuatorfrcrange="-0.144 0.144"/>
                    <geom quat="0.620809 0.620315 -0.338839 -0.339109" type="mesh" rgba="0.1 0.1 0.1 0.4" mesh="LThumb2_0.10" class="visual"/>
                  </body>
                </body>
              </body>
            </body>
          </body>
        </body>
      </body>
      <body name="RShoulder" pos="0 -0.098 0.1">
        <inertial pos="-0.00165 0.02663 0.00014" quat="0.572853 0.353499 -0.592494 0.442525" mass="0.09304" diaginertia="2.02186e-05 1.91002e-05 1.30704e-05"/>
        <joint name="RShoulderPitch" pos="0 0 0" axis="0 1 0" range="-2.08567 2.08567" actuatorfrcrange="-1.329 1.329" ref="-1.5"/>
        <geom type="mesh" rgba="0.8 0.4 0.9 1" mesh="RShoulderPitch_0.10" class="collision_3"/>
        <body name="RBicep">
          <inertial pos="0.02455 -0.00563 0.0033" quat="0.556969 0.570609 0.359404 0.484788" mass="0.15777" diaginertia="0.000287934 0.00025515 8.56154e-05"/>
          <joint name="RShoulderRoll" pos="0 0 0" axis="0 0 1" range="-1.32645 0.314159" actuatorfrcrange="-1.783 1.783"/>
          <geom type="mesh" rgba="0.3 0.1 0.6 1" mesh="RShoulderRoll_0.10" class="collision_4"/>
          <body name="RElbow" pos="0.105 -0.015 0">
            <inertial pos="-0.02744 0 -0.00014" quat="-0.000545392 0.711779 -0.000696018 0.702403" mass="0.06483" diaginertia="2.76333e-05 2.66179e-05 5.592e-06"/>
            <joint name="RElbowYaw" pos="0 0 0" axis="1 0 0" range="-2.08567 2.08567" actuatorfrcrange="-1.547 1.547"/>
            <body name="RForeArm">
              <inertial pos="0.02556 -0.00281 0.00076" quat="0.453039 0.428011 0.593606 0.509111" mass="0.07761" diaginertia="3.92326e-05 3.59586e-05 2.39457e-05"/>
              <joint name="RElbowRoll" pos="0 0 0" axis="0 0 1" range="0.0349066 1.54462" actuatorfrcrange="-1.532 1.532"/>
              <geom type="mesh" rgba="0.8 0.2 1 1" mesh="RElbowRoll_0.10" class="collision_1"/>
              <body name="r_wrist" pos="0.05595 0 0">
                <inertial pos="0.03434 0.00088 0.00308" quat="0.422432 0.617987 0.303847 0.589339" mass="0.18533" diaginertia="0.000139307 0.000131711 6.66137e-05"/>
                <joint name="RWristYaw" pos="0 0 0" axis="1 0 0" range="-1.82387 1.82387" actuatorfrcrange="-0.4075 0.4075" ref="-1.57"/>
                <geom type="mesh" rgba="0.1 0.4 0.6 1" mesh="RWristYaw_0.10" class="collision_2"/>
                <body name="r_gripper" pos="0.05775 0 -0.01213">
                  <inertial pos="0 0 0" mass="2e-06" diaginertia="1.1e-09 1.1e-09 1.1e-09"/>
                  <joint name="RHand" pos="0 0 0" axis="1 0 0" range="0 1" actuatorfrcrange="-0.292 0.292"/>
                </body>
                <body name="RFinger21_link" pos="0.06907 -0.01157 -0.00304" quat="0.672286 0.564114 0.308141 -0.367227">
                  <inertial pos="0 0 0" mass="2e-06" diaginertia="1.1e-09 1.1e-09 1.1e-09"/>
                  <joint name="RFinger21" pos="0 0 0" axis="0 0 1" range="0 0.999899" actuatorfrcrange="-0.144 0.144"/>
                  <geom quat="0.707388 -0.706825 0 0" type="mesh" rgba="0.1 0.1 0.1 0.4" mesh="RFinger21_0.10" class="visual"/>
                  <body name="RFinger22_link" pos="0.01436 0 0" quat="0.877607 0 0 -0.479381">
                    <inertial pos="0 0 0" mass="2e-06" diaginertia="1.1e-09 1.1e-09 1.1e-09"/>
                    <joint name="RFinger22" pos="0 0 0" axis="0 0 1" range="0 0.999899" actuatorfrcrange="-0.144 0.144"/>
                    <geom quat="0.707388 -0.706825 0 0" type="mesh" rgba="0.1 0.1 0.1 0.4" mesh="RFinger22_0.10" class="visual"/>
                    <body name="RFinger23_link" pos="0.01436 0 0" quat="0.877607 0 0 -0.479381">
                      <inertial pos="0 0 0" mass="2e-06" diaginertia="1.1e-09 1.1e-09 1.1e-09"/>
                      <joint name="RFinger23" pos="0 0 0" axis="0 0 1" range="0 0.999899" actuatorfrcrange="-0.144 0.144"/>
                      <geom quat="0.707388 -0.706825 0 0" type="mesh" rgba="0.1 0.1 0.1 0.4" mesh="RFinger23_0.10" class="visual"/>
                    </body>
                  </body>
                </body>
                <body name="RFinger11_link" pos="0.06907 0.01157 -0.00304" quat="0.564115 0.672285 0.367228 -0.30814">
                  <inertial pos="0 0 0" mass="2e-06" diaginertia="1.1e-09 1.1e-09 1.1e-09"/>
                  <joint name="RFinger11" pos="0 0 0" axis="0 0 1" range="0 0.999899" actuatorfrcrange="-0.144 0.144"/>
                  <geom quat="0.707388 -0.706825 0 0" type="mesh" rgba="0.1 0.1 0.1 0.4" mesh="RFinger11_0.10" class="visual"/>
                  <body name="RFinger12_link" pos="0.01436 0 0" quat="0.877607 0 0 -0.479381">
                    <inertial pos="0 0 0" mass="2e-06" diaginertia="1.1e-09 1.1e-09 1.1e-09"/>
                    <joint name="RFinger12" pos="0 0 0" axis="0 0 1" range="0 0.999899" actuatorfrcrange="-0.144 0.144"/>
                    <geom quat="0.707388 -0.706825 0 0" type="mesh" rgba="0.1 0.1 0.1 0.4" mesh="RFinger12_0.10" class="visual"/>
                    <body name="RFinger13_link" pos="0.01436 0 0" quat="0.877607 0 0 -0.479381">
                      <inertial pos="0 0 0" mass="2e-06" diaginertia="1.1e-09 1.1e-09 1.1e-09"/>
                      <joint name="RFinger13" pos="0 0 0" axis="0 0 1" range="0 0.999899" actuatorfrcrange="-0.144 0.144"/>
                      <geom quat="0.707388 -0.706825 0 0" type="mesh" rgba="0.1 0.1 0.1 0.4" mesh="RFinger13_0.10" class="visual"/>
                    </body>
                  </body>
                </body>
                <body name="RThumb1_link" pos="0.04895 0 -0.02638" quat="0.706908 -0.70691 0.0167209 0.016721">
                  <inertial pos="0 0 0" mass="2e-06" diaginertia="1.1e-09 1.1e-09 1.1e-09"/>
                  <joint name="RThumb1" pos="0 0 0" axis="0 0 1" range="0 0.999899" actuatorfrcrange="-0.144 0.144"/>
                  <geom quat="0.620809 0.620315 -0.338839 -0.339109" type="mesh" rgba="0.1 0.1 0.1 0.4" mesh="RThumb1_0.10" class="visual"/>
                  <body name="RThumb2_link" pos="0.01236 -0.0015 0" quat="0.877607 0 0 -0.479381">
                    <inertial pos="0 0 0" mass="2e-06" diaginertia="1.1e-09 1.1e-09 1.1e-09"/>
                    <joint name="RThumb2" pos="0 0 0" axis="0 0 1" range="0 0.999899" actuatorfrcrange="-0.144 0.144"/>
                    <geom quat="0.620809 0.620315 -0.338839 -0.339109" type="mesh" rgba="0.1 0.1 0.1 0.4" mesh="RThumb2_0.10" class="visual"/>
                  </body>
                </body>
              </body>
            </body>
          </body>
        </body>
      </body>
    </body>
  </worldbody>

<actuator>
  <position name="HeadYaw_position" joint="HeadYaw" kp="20" kv="0.4"/>
  <position name="HeadPitch_position" joint="HeadPitch" kp="40" kv="0.8"/>

  <position name="LShoulderPitch_position" joint="LShoulderPitch" kp="50" kv="0.7"/>
  <position name="LShoulderRoll_position" joint="LShoulderRoll" kp="60" kv="0.6"/>
  <position name="LElbowYaw_position" joint="LElbowYaw" kp="40" kv="0.5"/>
  <position name="LElbowRoll_position" joint="LElbowRoll" kp="60" kv="0.6"/>

  <position name="RShoulderPitch_position" joint="RShoulderPitch" kp="50" kv="0.7"/>
  <position name="RShoulderRoll_position" joint="RShoulderRoll" kp="60" kv="0.6"/>
  <position name="RElbowYaw_position" joint="RElbowYaw" kp="40" kv="0.5"/>
  <position name="RElbowRoll_position" joint="RElbowRoll" kp="60" kv="0.6"/>

  <position name="LHipYawPitch_position" joint="LHipYawPitch" kp="80" kv="1.5"/>
  <position name="LHipRoll_position" joint="LHipRoll" kp="90" kv="1.5"/>
  <position name="LHipPitch_position" joint="LHipPitch" kp="70" kv="1.5"/>
  <position name="LKneePitch_position" joint="LKneePitch" kp="70" kv="1.5"/>
  <position name="LAnklePitch_position" joint="LAnklePitch" kp="70" kv="1.5"/>
  <position name="LAnkleRoll_position" joint="LAnkleRoll" kp="90" kv="1.5"/>

  <position name="RHipYawPitch_position" joint="RHipYawPitch" kp="80" kv="1.5"/>
  <position name="RHipRoll_position" joint="RHipRoll" kp="90" kv="1.5"/>
  <position name="RHipPitch_position" joint="RHipPitch" kp="70" kv="1.5"/>
  <position name="RKneePitch_position" joint="RKneePitch" kp="70" kv="1.5"/>
  <position name="RAnklePitch_position" joint="RAnklePitch" kp="70" kv="1.5"/>
  <position name="RAnkleRoll_position" joint="RAnkleRoll" kp="90" kv="1.5"/>

  <position name="LHand_position" joint="LHand" kp="10" kv="0.2"/>
  <position name="LWristYaw_position" joint="LWristYaw" kp="15" kv="0.3"/>

  <position name="RHand_position" joint="RHand" kp="10" kv="0.2"/>
  <position name="RWristYaw_position" joint="RWristYaw" kp="15" kv="0.3"/>
</actuator>


  <sensor>
    <jointpos name="HeadYaw_pos" joint="HeadYaw" noise="0.002"/>
    <jointpos name="HeadPitch_pos" joint="HeadPitch" noise="0.002"/>
    
    <jointpos name="LShoulderPitch_pos" joint="LShoulderPitch" noise="0.002"/>
    <jointpos name="LShoulderRoll_pos" joint="LShoulderRoll" noise="0.002"/>
    <jointpos name="LElbowYaw_pos" joint="LElbowYaw" noise="0.002"/>
    <jointpos name="LElbowRoll_pos" joint="LElbowRoll" noise="0.002"/>
    <jointpos name="LWristYaw_pos" joint="LWristYaw" noise="0.002"/>
    <jointpos name="LHand_pos" joint="LHand" noise="0.002"/>

    <jointpos name="RShoulderPitch_pos" joint="RShoulderPitch" noise="0.002"/>
    <jointpos name="RShoulderRoll_pos" joint="RShoulderRoll" noise="0.002"/>
    <jointpos name="RElbowYaw_pos" joint="RElbowYaw" noise="0.002"/>
    <jointpos name="RElbowRoll_pos" joint="RElbowRoll" noise="0.002"/>
    <jointpos name="RWristYaw_pos" joint="RWristYaw" noise="0.002"/>
    <jointpos name="RHand_pos" joint="RHand" noise="0.002"/>

    <jointpos name="LHipYawPitch_pos" joint="LHipYawPitch" noise="0.002"/>
    <jointpos name="LHipRoll_pos" joint="LHipRoll" noise="0.002"/>
    <jointpos name="LHipPitch_pos" joint="LHipPitch" noise="0.002"/>
    <jointpos name="LKneePitch_pos" joint="LKneePitch" noise="0.002"/>
    <jointpos name="LAnklePitch_pos" joint="LAnklePitch" noise="0.002"/>
    <jointpos name="LAnkleRoll_pos" joint="LAnkleRoll" noise="0.002"/>

    <jointpos name="RHipYawPitch_pos" joint="RHipYawPitch" noise="0.002"/>
    <jointpos name="RHipRoll_pos" joint="RHipRoll" noise="0.002"/>
    <jointpos name="RHipPitch_pos" joint="RHipPitch" noise="0.002"/>
    <jointpos name="RKneePitch_pos" joint="RKneePitch" noise="0.002"/>
    <jointpos name="RAnklePitch_pos" joint="RAnklePitch" noise="0.002"/>
    <jointpos name="RAnkleRoll_pos" joint="RAnkleRoll" noise="0.002"/>


    <accelerometer name="accelerometer" noise="0.05" site="accelerometer_site"/>
    <gyro name="gyro" noise="0.02" site="gyrometer_site"/>
    <magnetometer name="compass" noise="0.001" site="gyrometer_site"/>

    <force name="LFsrFL" site="LFsrFL_site"/>
    <force name="LFsrFR" site="LFsrFR_site"/>
    <force name="LFsrRL" site="LFsrRL_site"/>
    <force name="LFsrRR" site="LFsrRR_site"/>
    
    <force name="RFsrFL" site="RFsrFL_site"/>
    <force name="RFsrFR" site="RFsrFR_site"/>
    <force name="RFsrRL" site="RFsrRL_site"/>
    <force name="RFsrRR" site="RFsrRR_site"/>

    <force name="LFootForce" site="LFsrFL_site"/>
    <torque name="LFootTorque" site="LFsrFL_site"/>
    <force name="RFootForce" site="RFsrFL_site"/>
    <torque name="RFootTorque" site="RFsrFL_site"/>

    <touch name="BumperLFootLeft" site="BumperLFootLeft_site"/>
    <touch name="BumperLFootRight" site="BumperLFootRight_site"/>
    <touch name="BumperRFootLeft" site="BumperRFootLeft_site"/>
    <touch name="BumperRFootRight" site="BumperRFootRight_site"/>
  </sensor>

</mujoco>
